<?xml version="1.0"?>
<robot name="r200_wheels" xmlns:xacro="http://www.ros.org/wiki/xacro"> 

  <xacro:macro name="r200_wheel" params="prefix parent *origin">

    <joint name="${prefix}_wheel_joint" type="continuous">
      <xacro:insert_block name="origin" />
      <parent link="${parent}"/>
      <child link="${prefix}_wheel_link"/>
      <axis xyz="0 1 0" rpy="0 0 0" />
      <limit effort="30" velocity="2.0"/>
      <dynamics damping="0" friction="0"/>
    </joint>

    <link name="${prefix}_wheel_link">
      <inertial>
        <mass value="2.5"/>
        <origin rpy="0 0 0" xyz="0 0 0"/>
        <inertia ixx="0.026" ixy="0.0" ixz="0.0" iyy="0.044" iyz="0.0" izz="0.026"/>   
      </inertial>
      <visual>
        <geometry>
          <mesh filename="package://r200_description/meshes/wheel.stl" />
        </geometry>
        <material name="Black"/>
        <origin rpy="0 0 0" xyz="0 0 0"/>
      </visual>
      <collision>
        <geometry>
          <cylinder radius="0.1665" length="0.114"/>
        </geometry>
        <origin rpy="${M_PI/2} 0 0" xyz="0 -0.057 0"/>
      </collision>
    </link>

  </xacro:macro>
      

</robot>
